<robot name="skyforge" xmlns:xacro="http://ros.org/wiki/xacro">

  <!-- Properties -->
  <xacro:property name="mesh_dir" value="package://skyforge/meshes"/>
  <xacro:property name="joint_limit" value="${pi*0.5}"/>
  <xacro:property name="scale" value="0.001 0.001 0.001"/>
  <xacro:property name="point_2" value="0.212951"/>
  <xacro:property name="point_3" value="0.425902"/>

  <!-- World Link -->
  <link name="world"/>
  <link name="base_link"/>

  <joint name="world_to_base" type="fixed">
    <parent link="world"/>
    <child link="base_link"/>
    <origin xyz="0 0 0" rpy="0 0 0"/>
  </joint>

  <!-- Section 1 -->
  <link name="Section_1">
    <visual>
      <origin xyz="0 0 0" rpy="0 0 0"/>
      <geometry>
        <mesh filename="${mesh_dir}/Section_1_Fixed.stl" scale="${scale}"/>
      </geometry>
      <material name="Section_1_Material">
        <color rgba="0.498 1.0 0.831 1.0"/>
      </material>
    </visual>

    <collision>
      <origin xyz="0 0 0" rpy="0 0 0"/>
      <geometry>
        <mesh filename="${mesh_dir}/Section_1_Fixed.stl" scale="${scale}"/>
      </geometry>
    </collision>
    
    <inertial>
      <origin xyz="0 0 0" rpy="0 0 0"/>
      <mass value="1.647975"/>
      <inertia ixx="0.01" ixy="0" ixz="0" iyy="0.01" iyz="0" izz="0.01"/>
    </inertial>
  </link>

  <joint name="settling" type="fixed">
    <parent link="base_link"/>
    <child link="Section_1"/>
    <origin xyz="0 0 0" rpy="0 0 0"/>
  </joint>

  <!-- Section 2 -->
  <link name="Section_2">
    <visual>
      <origin xyz="0 0 0" rpy="0 0 0"/>
      <geometry>
        <mesh filename="${mesh_dir}/Section_2_Fixed.stl" scale="${scale}"/>
      </geometry>
      <material name="Section_2_Material">
        <color rgba="0.443 0.522 0.259 1.0"/>
      </material>
    </visual>

    <collision>
      <origin xyz="0 0 0" rpy="0 0 0"/>
      <geometry>
        <mesh filename="${mesh_dir}/Section_2_Fixed.stl" scale="${scale}"/>
      </geometry>
    </collision>
    
    <inertial>
      <origin xyz="0 0 0" rpy="0 0 0"/>
      <mass value="2.695605"/>
      <inertia ixx="0.01" ixy="0" ixz="0" iyy="0.01" iyz="0" izz="0.01"/>
    </inertial>
  </link>

  <joint name="joint1" type="revolute">
    <parent link="Section_1"/>
    <child link="Section_2"/>
    <origin xyz="0 0 0" rpy="0 0 0"/>
    <axis xyz="0 0 1"/>
    <limit lower="-${joint_limit}" upper="${joint_limit}" effort="10" velocity="1"/>
  </joint>

  <!-- Section 3 -->
  <link name="Section_3">
    <visual>
      <origin xyz="0 0 0" rpy="0 0 0"/>
      <geometry>
        <mesh filename="${mesh_dir}/Section_3_Fixed.stl" scale="${scale}"/>
      </geometry>
      <material name="Section_3_Material">
        <color rgba="1.0 0.0 0.0 1.0"/>
      </material>
    </visual>

    <collision>
      <origin xyz="0 0 0" rpy="0 0 0"/>
      <geometry>
        <mesh filename="${mesh_dir}/Section_3_Fixed.stl" scale="${scale}"/>
      </geometry>
    </collision>
    
    <inertial>
      <origin xyz="0 0 0" rpy="0 0 0"/>
      <mass value="2.639263"/>
      <inertia ixx="0.01" ixy="0" ixz="0" iyy="0.01" iyz="0" izz="0.01"/>
    </inertial>
  </link>

  <joint name="joint2" type="revolute">
    <parent link="Section_2"/>
    <child link="Section_3"/>
    <origin xyz="${point_2} 0 0" rpy="0 0 0"/>
    <axis xyz="0 0 1"/>
    <limit lower="-${joint_limit}" upper="${joint_limit}" effort="10" velocity="1"/>
  </joint>

  <!-- Section 4 -->
  <link name="Section_4">
    <visual>
      <origin xyz="0 0 0" rpy="0 0 0"/>
      <geometry>
        <mesh filename="${mesh_dir}/Section_4_Fixed.stl" scale="${scale}"/>
      </geometry>
      <material name="Section_4_Material">
        <color rgba="1.0 0.7137 0.7568 1.0"/>
      </material>
    </visual>

    <collision>
      <origin xyz="0 0 0" rpy="0 0 0"/>
      <geometry>
        <mesh filename="${mesh_dir}/Section_4_Fixed.stl" scale="${scale}"/>
      </geometry>
    </collision>

    <inertial>
      <origin xyz="0 0 0" rpy="0 0 0"/>
      <mass value="1.164282"/>
      <inertia ixx="0.01" ixy="0" ixz="0" iyy="0.01" iyz="0" izz="0.01"/>
    </inertial>
  </link>

  <joint name="joint3" type="revolute">
    <parent link="Section_3"/>
    <child link="Section_4"/>
    <origin xyz="${point_2} 0 0" rpy="0 0 0"/>
    <axis xyz="0 0 1"/>
    <limit lower="-${joint_limit}" upper="${joint_limit}" effort="10" velocity="1"/>
  </joint>

  <!-- Gazebo Plugin -->
  <gazebo>
    <plugin name="gazebo_ros_control" filename="libgazebo_ros2_control.so">
      <ros_control_plugin>gazebo_ros_control</ros_control_plugin>
    </plugin>
  </gazebo>

  <!-- Joint Transmissions -->
  <transmission name="joint1_trans">
    <type>transmission_interface/SimpleTransmission</type>
    <joint name="joint1">
      <hardwareInterface>hardware_interface/PositionJointInterface</hardwareInterface>
    </joint>
    <actuator name="joint1_motor">
      <mechanicalReduction>1</mechanicalReduction>
    </actuator>
  </transmission>

  <transmission name="joint2_trans">
    <type>transmission_interface/SimpleTransmission</type>
    <joint name="joint2">
      <hardwareInterface>hardware_interface/PositionJointInterface</hardwareInterface>
    </joint>
    <actuator name="joint2_motor">
      <mechanicalReduction>1</mechanicalReduction>
    </actuator>
  </transmission>

  <transmission name="joint3_trans">
    <type>transmission_interface/SimpleTransmission</type>
    <joint name="joint3">
      <hardwareInterface>hardware_interface/PositionJointInterface</hardwareInterface>
    </joint>
    <actuator name="joint3_motor">
      <mechanicalReduction>1</mechanicalReduction>
    </actuator>
  </transmission>

  <!-- Gazebo PID controllers for each joint -->
  <gazebo reference="joint1">
    <kp>10</kp>
    <kd>1</kd>
    <ki>0</ki>
    <minEffort>-10</minEffort>
    <maxEffort>10</maxEffort>
  </gazebo>

  <gazebo reference="joint2">
    <kp>10</kp>
    <kd>1</kd>
    <ki>0</ki>
    <minEffort>-10</minEffort>
    <maxEffort>10</maxEffort>
  </gazebo>

  <gazebo reference="joint3">
    <kp>10</kp>
    <kd>1</kd>
    <ki>0</ki>
    <minEffort>-10</minEffort>
    <maxEffort>10</maxEffort>
  </gazebo>

</robot>
